Workbook
Name Slicer_Representative: #N/A
Name Slicer_Representative1: #N/A
Name Slicer_Representative2: #N/A

Sheet Basic
A1: Emp ID | B1: Name | C1: Gender | D1: Department | E1: Salary | F1: Start Date | G1: FTE | H1: Employee type | I1: Work location
A2: PR00770 | B2: Beryl Burnsyde | C2: Male | D2: Legal | E2: 29774.76 | F2: 44105 | G2: 1 | H2: Permanent | I2: Wellington, New Zealand
A3: PR03034 | B3: Sreenivasa Naik Gudiwada | C3: Male | D3: Sales | E3: 32192.15 | F3: 44473 | G3: 1 | H3: Permanent | I3: Hyderabad, India
A4: PR01055 | B4: Devasree Fullara Saurin | C4: Male | D4: Accounting | E4: 35936.31 | F4: 43241 | G4: 1 | H4: Permanent | I4: Chennai, India
A5: PR03844 | B5: Brose MacCorkell | C5: Female | D5: Human Resources | E5: 35943.62 | F5: 44078 | G5: 1 | H5: Permanent | I5: Columbus, USA
A6: PR01956 | B6: Jamesy O'Ferris | C6: Male | D6: Accounting | E6: 36547.58 | F6: 43416 | G6: 1 | H6: Permanent | I6: Remote
A7: PR01956 | B7: Jamesy O'Ferris | C7: Male | D7: Accounting | E7: 36547.58 | F7: 43416 | G7: 1 | H7: Permanent | I7: Remote
A8: PR03137 | B8: Jagajeet Viraj | C8: Male | D8: Support | E8: 36714.38 | F8: 44175 | G8: 1 | H8: Permanent | I8: Chennai, India
A9: PR02782 | B9: Isaak Rawne | C9: Male | D9: Marketing | E9: 37362.3 | F9: 43642 | G9: 1 | H9: Permanent | I9: Auckland, New Zealand
A10: PR03271 | B10: Stan Tolliday | C10: Female | D10: Sales | E10: 39535.49 | F10: 43397 | G10: 0.3 | H10: Permanent | I10: Remote
A11: PR02275 | B11: Louise Lamming | C11: Female | D11: Sales | E11: 41934.71 | F11: 43780 | G11: 1 | H11: Permanent | I11: Remote
A12: PR04366 | B12: Carry Loblie | C12: Female | D12: Sales | E12: 47551.89 | F12: 43468 | G12: 1 | H12: Permanent | I12: Auckland, New Zealand
A13: PR01943 | B13: Rameshwari Chikodi | C13: Male | D13: Human Resources | E13: 48525.71 | F13: 43264 | G13: 1 | H13: Permanent | I13: Hyderabad, India
... A53: PR01159 | B53: Mollie Hanway | C53: Male | D53: ??? | E53: 112645.99 | F53: 43759 | G53: 0.6 | H53: Permanent | I53: Seattle, USA
A54: PR04601 | B54: Yedukondalu Panditula | D54: Support | E54: 104802.63 | F54: 44502 | G54: 1 | H54: Permanent | I54: Hyderabad, India
A55: SQ00022 | B55: Carlin Demke | C55: Male | D55: Business Development | E55: 110042.37 | F55: 43914 | G55: 1 | H55: Permanent | I55: Columbus, USA
A56: PR02288 | B56: Althea Bronger | C56: Male | D56: Product Management | E56: 104335.04 | F56: 43874 | G56: 1 | H56: Permanent | I56: Columbus, USA
A57: PR02208 | B57: Gowri Sankar Chakrala | C57: Female | D57: Training | E57: 102934.09 | F57: 44315 | G57: 1 | H57: Permanent | I57: Hyderabad, India
A58: PR04686 | B58: Oona Donan | C58: Female | D58: Business Development | E58: 98000 | F58: 43710 | G58: 0.9 | H58: Permanent | I58: Seattle, USA

Sheet Medals
A1: Rank | B1: Country | C1: Gold | D1: Silver | E1: Bronze | F1: Total | G1: Division
A2: 1 | B2: United States | C2: 39 | D2: 41 | E2: 33 | F2: 113 | G2: 0.34513274
A3: 2 | B3: China | C3: 38 | D3: 32 | E3: 19 | F3: 89 | G3: 0.42696629
A4: 3 | B4: Japan | C4: 27 | D4: 14 | E4: 17 | F4: 58 | G4: 0.46551724
A5: 4 | B5: Great Britain | C5: 22 | D5: 20 | E5: 22 | F5: 64 | G5: 0.34375
A6: 5 | B6: ROC | C6: 20 | D6: 28 | E6: 23 | F6: 71 | G6: 0.28169014
A7: 6 | B7: Australia | C7: 17 | D7: 7 | E7: 22 | F7: 46 | G7: 0.36956522
A8: 7 | B8: Netherlands | C8: 10 | D8: 12 | E8: 14 | F8: 36 | G8: 0.27777778
A9: 8 | B9: France | C9: 10 | D9: 12 | E9: 11 | F9: 33 | G9: 0.3030303
A10: 9 | B10: Germany | C10: 10 | D10: 11 | E10: 16 | F10: 37 | G10: 0.27027027
A11: 10 | B11: Italy | C11: 10 | D11: 10 | E11: 20 | F11: 40 | G11: 0.25
A12: 11 | B12: Canada | C12: 7 | D12: 7 | E12: 10 | F12: 24 | G12: 0.29166667
A13: 12 | B13: Brazil | C13: 7 | D13: 6 | E13: 8 | F13: 21 | G13: 0.33333333
... A94: 86 | B94: Syria | C94: 0 | D94: 0 | E94: 1 | F94: 1 | G94: 0

Sheet Staff
A1: Emp ID | B1: First name | C1: Last name | D1: Gender | E1: Department | F1: Salary | G1: Salary bucket | H1: Start Date | I1: FTE | J1: Employee type | K1: Work type | L1: Work location | M1: Age | N1: Total Years
A2: PR00147 | B2: Minerva | C2: Ricardot | D2: Male | E2: Engineering | F2: 120000 | G2: Above 100k | H2: 43416 | I2: 1 | J2: Permanent | K2: Full time | L2: Remote | M2: 2692 | N2: 7
A3: PR04686 | B3: Oona | C3: Donan | D3: Female | E3: Business Development | F3: 98000 | G3: 50k to 100k | H3: 43710 | I3: 0.9 | J3: Permanent | K3: Part time | L3: Seattle, USA | M3: 2398 | N3: 7
A4: SQ04612 | B4: Mick | C4: Spraberry | D4: Female | E4: Services | F4: 120000 | G4: Above 100k | H4: 43902 | I4: 0.9 | J4: Permanent | K4: Part time | L4: Remote | M4: 2206 | N4: 6
A5: VT01803 | B5: Freddy | C5: Linford | D5: Female | E5: Training | F5: 93128.34 | G5: 50k to 100k | H5: 43164 | I5: 1 | J5: Fixed Term | K5: Full time | L5: Seattle, USA | M5: 2944 | N5: 8
A6: TN02749 | B6: Parasuramudu | C6: Jamakayala | D6: Female | E6: Training | F6: 57002.02 | G6: 50k to 100k | H6: 43192 | I6: 0.7 | J6: Permanent | K6: Part time | L6: Hyderabad, India | M6: 2916 | N6: 8
A7: SQ00144 | B7: Collen | C7: Dunbleton | D7: Male | E7: Engineering | F7: 118976.16 | G7: Above 100k | H7: 44120 | I7: 1 | J7: Permanent | K7: Full time | L7: Wellington, New Zealand | M7: 1988 | N7: 5
A8: PR04601 | B8: Yedukondalu | C8: Panditula | D8: Missing | E8: Support | F8: 104802.63 | G8: Above 100k | H8: 44502 | I8: 1 | J8: Permanent | K8: Full time | L8: Hyderabad, India | M8: 1606 | N8: 4
A9: SQ01854 | B9: Jessica | C9: Callcott | D9: Female | E9: Marketing | F9: 66017.18 | G9: 50k to 100k | H9: 43643 | I9: 0.9 | J9: Permanent | K9: Part time | L9: Remote | M9: 2465 | N9: 7
A10: SQ00612 | B10: Leena | C10: Bruckshaw | D10: Male | E10: Research and Development | F10: 74279.01 | G10: 50k to 100k | H10: 43466 | I10: 1 | J10: Permanent | K10: Full time | L10: Wellington, New Zealand | M10: 2642 | N10: 7
A11: PR00419 | B11: Billi | C11: Fellgate | D11: Female | E11: Business Development | F11: 68980.52 | G11: 50k to 100k | H11: 43494 | I11: 0.8 | J11: Permanent | K11: Part time | L11: Remote | M11: 2614 | N11: 7
A12: VT00578 | B12: Magnum | C12: Locksley | D12: Female | E12: Services | F12: 42314.39 | G12: under 50k | H12: 44487 | I12: 1 | J12: Fixed Term | K12: Full time | L12: Remote | M12: 1621 | N12: 4
A13: TN01281 | B13: Cletus | C13: McGarahan | D13: Female | E13: Engineering | F13: 114425.19 | G13: Above 100k | H13: 43857 | I13: 1 | J13: Permanent | K13: Full time | L13: Wellington, New Zealand | M13: 2251 | N13: 6
... A261: SQ03625 | B261: Fidela | C261: Artis | D261: Female | E261: Sales | F261: 78020.39 | G261: 50k to 100k | H261: 43899 | I261: 1 | J261: Permanent | K261: Full time | L261: Remote | M261: 2209 | N261: 6

Sheet Formulas
D6: Department | E6: Head count | F6: Total salary
D7: Engineering | E7: =COUNTIFS(Staff[Department],D7) -> 26 | F7: {=SUMIFS(Staff[Salary],Staff[Department],D7:D18)} -> 2131387.5 | G7: {=AVERAGEIFS(Staff[Salary],Staff[Department],D7:D18)} -> 81976.442
D8: Business Development | E8: =COUNTIFS(Staff[Department],D8) -> 26 | F8: 2074327 | G8: 79781.806
D9: Services | E9: =COUNTIFS(Staff[Department],D9) -> 21 | F9: 1568153.5 | G9: 74673.975
D10: Training | E10: =COUNTIFS(Staff[Department],D10) -> 24 | F10: 2013215.2 | G10: 83883.965
D11: Support | E11: =COUNTIFS(Staff[Department],D11) -> 17 | F11: 1129351.7 | G11: 66432.456
D12: Marketing | E12: =COUNTIFS(Staff[Department],D12) -> 12 | F12: 773295.6 | G12: 64441.3
D13: Research and Development | E13: =COUNTIFS(Staff[Department],D13) -> 18 | F13: 1204393.8 | G13: 66910.766
D14: Human Resources | E14: =COUNTIFS(Staff[Department],D14) -> 22 | F14: 1608406.3 | G14: 73109.378
D15: Accounting | E15: =COUNTIFS(Staff[Department],D15) -> 26 | F15: 1814980.6 | G15: 69806.946
D16: Sales | E16: =COUNTIFS(Staff[Department],D16) -> 18 | F16: 1294147.7 | G16: 71897.096
D17: Product Management | E17: =COUNTIFS(Staff[Department],D17) -> 29 | F17: 2180192.9 | G17: 75179.064
D18: Legal | E18: =COUNTIFS(Staff[Department],D18) -> 21 | F18: 1412092.9 | G18: 67242.518
D21: All employees with more than 100k salary
D22: {=Staff[#Headers]} -> Emp ID | E22: First name | F22: Last name | G22: Gender | H22: Department | I22: Salary | J22: Salary bucket | K22: Start Date | L22: FTE | M22: Employee type | N22: Work type | O22: Work location | P22: Age | Q22: Total Years
D23: {=_xlfn._xlws.FILTER(Staff[],Staff[Salary]>100000)} -> PR00147 | E23: Minerva | F23: Ricardot | G23: Male | H23: Engineering | I23: 120000 | J23: Above 100k | K23: 43416 | L23: 1 | M23: Permanent | N23: Full time | O23: Remote | P23: 2692 | Q23: 7
D24: SQ04612 | E24: Mick | F24: Spraberry | G24: Female | H24: Services | I24: 120000 | J24: Above 100k | K24: 43902 | L24: 0.9 | M24: Permanent | N24: Part time | O24: Remote | P24: 2206 | Q24: 6
D25: SQ00144 | E25: Collen | F25: Dunbleton | G25: Male | H25: Engineering | I25: 118976.16 | J25: Above 100k | K25: 44120 | L25: 1 | M25: Permanent | N25: Full time | O25: Wellington, New Zealand | P25: 1988 | Q25: 5
D26: PR04601 | E26: Yedukondalu | F26: Panditula | G26: Missing | H26: Support | I26: 104802.63 | J26: Above 100k | K26: 44502 | L26: 1 | M26: Permanent | N26: Full time | O26: Hyderabad, India | P26: 1606 | Q26: 4
D27: TN01281 | E27: Cletus | F27: McGarahan | G27: Female | H27: Engineering | I27: 114425.19 | J27: Above 100k | K27: 43857 | L27: 1 | M27: Permanent | N27: Full time | O27: Wellington, New Zealand | P27: 2251 | Q27: 6
D28: PR02288 | E28: Althea | F28: Bronger | G28: Male | H28: Product Management | I28: 104335.04 | J28: Above 100k | K28: 43874 | L28: 1 | M28: Permanent | N28: Full time | O28: Columbus, USA | P28: 2234 | Q28: 6
D29: SQ01620 | E29: Westbrook | F29: Brandino | G29: Male | H29: Legal | I29: 113616.23 | J29: Above 100k | K29: 43255 | L29: 1 | M29: Permanent | N29: Full time | O29: Remote | P29: 2853 | Q29: 8
D30: VT04681 | E30: Nickolai | F30: Artin | G30: Female | H30: Product Management | I30: 110906.35 | J30: Above 100k | K30: 43434 | L30: 1 | M30: Temporary | N30: Full time | O30: Wellington, New Zealand | P30: 2674 | Q30: 7
D31: TN04246 | E31: Shaylyn | F31: Ransbury | G31: Female | H31: Support | I31: 100371.31 | J31: Above 100k | K31: 44067 | L31: 0.8 | M31: Fixed Term | N31: Part time | O31: Auckland, New Zealand | P31: 2041 | Q31: 6
D32: VT02801 | E32: Shellysheldon | F32: Mahady | G32: Male | H32: Training | I32: 114691.03 | J32: Above 100k | K32: 44039 | L32: 1 | M32: Temporary | N32: Full time | O32: Wellington, New Zealand | P32: 2069 | Q32: 6
D33: PR02208 | E33: Gowri | F33: Sankar | G33: Female | H33: Training | I33: 102934.09 | J33: Above 100k | K33: 44315 | L33: 1 | M33: Permanent | N33: Full time | O33: Hyderabad, India | P33: 1793 | Q33: 5
D34: VT04093 | E34: Prasanna | F34: Lakshmi | G34: Female | H34: Training | I34: 116767.63 | J34: Above 100k | K34: 43949 | L34: 0.4 | M34: Temporary | N34: Part time | O34: Chennai, India | P34: 2159 | Q34: 6
D35: VT03421 | E35: Alic | F35: Bagg | G35: Male | H35: Legal | I35: 113747.56 | J35: Above 100k | K35: 44270 | L35: 0.7 | M35: Temporary | N35: Part time | O35: Columbus, USA | P35: 1838 | Q35: 5
... D69: VT03421 | E69: Alic | F69: Bagg | G69: Male | H69: Legal | I69: 113747.56 | J69: Above 100k | K69: 44270 | L69: 0.7 | M69: Temporary | N69: Part time | O69: Columbus, USA | P69: 1838 | Q69: 5
D74: All employees with >100k salary with columns 1,2,3,5,6
D75: {=_xlfn.CHOOSECOLS(Staff[#Headers],1,2,3,5,6)} -> Emp ID | E75: First name | F75: Last name | G75: Department | H75: Salary
D76: {=_xlfn.CHOOSECOLS(_xlfn._xlws.FILTER(Staff[],Staff[Salary]>100000),1,2,3,5,6)} -> PR00147 | E76: Minerva | F76: Ricardot | G76: Engineering | H76: 120000
D77: SQ04612 | E77: Mick | F77: Spraberry | G77: Services | H77: 120000
D78: SQ00144 | E78: Collen | F78: Dunbleton | G78: Engineering | H78: 118976.16
D79: PR04601 | E79: Yedukondalu | F79: Panditula | G79: Support | H79: 104802.63
D80: TN01281 | E80: Cletus | F80: McGarahan | G80: Engineering | H80: 114425.19
D81: PR02288 | E81: Althea | F81: Bronger | G81: Product Management | H81: 104335.04
D82: SQ01620 | E82: Westbrook | F82: Brandino | G82: Legal | H82: 113616.23
D83: VT04681 | E83: Nickolai | F83: Artin | G83: Product Management | H83: 110906.35
D84: TN04246 | E84: Shaylyn | F84: Ransbury | G84: Support | H84: 100371.31
...

Sheet Pivot tables
B1: Pivot Tables in Excel
B5: Analysis Themes: | D5: Concepts introduced:
B6: 1 | C6: How many calls we are getting by customer? | D6: Pivoting data
B7: 2 | C7: How satisfied are our customers? | D7: Chaging calculation mode
B8: 3 | C8: Who are our top 10 customers? | D8: Filters
B9: 4 | C9: Top 10 customers for a specific representative? | D9: Report filters / slicers
B10: 5 | C10: Call duration analysis | D10: Grouping / bucketing
B11: 6 | C11: How busy is our call centre in 2023? | D11: Trends / pivot chart
B12: 7 | C12: YTD Sales Analysis | D12: Value settings
B13: 8 | C13: Which days of week are the busiest? | D13: Conditional formatting
B14: 9 | C14: Is there a link between call duration and satisfaction rating? | D14: Adding columns, refresh, scatter graph
B15: 10 | C15: Should we hire extra people in any specific months? | D15: Conditional formatting
B17: H1 | C17: Time wasters: Which customers call most but buy least?
B18: H2 | C18: Rep training: Which rep(s) could use satisfaction training program?

Sheet 1 & 2
A3: Row Labels | B3: Count of Call number | C3: Average of Satisfaction Rating
A4: C0001 | B4: 65 | C4: 3.8307692
A5: C0002 | B5: 63 | C5: 4.0730159
A6: C0003 | B6: 50 | C6: 4.018
A7: C0004 | B7: 82 | C7: 3.9768293
A8: C0005 | B8: 79 | C8: 3.9797468
A9: C0006 | B9: 62 | C9: 3.7774194
A10: C0007 | B10: 67 | C10: 3.8522388
A11: C0008 | B11: 59 | C11: 3.9016949
A12: C0009 | B12: 69 | C12: 3.626087
A13: C0010 | B13: 72 | C13: 3.8638889
A14: C0011 | B14: 74 | C14: 3.9837838
A15: C0012 | B15: 70 | C15: 4.13
... A19: Grand Total | B19: 1000 | C19: 3.8854

Sheet 3&4
A3: Row Labels | B3: Sum of Purchase Amount
A4: C0012 | B4: 2070
A5: C0011 | B5: 1747
A6: C0004 | B6: 1722
A7: C0013 | B7: 1722
A8: C0009 | B8: 1566
A9: C0002 | B9: 1508
A10: C0006 | B10: 1484
A11: C0007 | B11: 1416
A12: C0005 | B12: 1196
A13: C0008 | B13: 1193
A14: Grand Total | B14: 15624

Sheet 6&7
A3: Row Labels | B3: Count of Call number
A4: Jan | B4: 10
A5: Feb | B5: 11
A6: Mar | B6: 30
A7: Apr | B7: 23
A8: May | B8: 22
A9: Jun | B9: 11
A10: Jul | B10: 17
A11: Aug | B11: 12
A12: Sep | B12: 13
A13: Oct | B13: 15
A14: Nov | B14: 8
A15: Dec | B15: 14
A16: Grand Total | B16: 186
A20: Row Labels | B20: Sum of Purchase Amount
A21: Jan | B21: 1291
A22: Feb | B22: 1060
A23: Mar | B23: 2165
A24: Apr | B24: 1795
A25: May | B25: 2212
A26: Jun | B26: 675
A27: Jul | B27: 1535
A28: Aug | B28: 1433
A29: Sep | B29: 1122
A30: Oct | B30: 1245
A31: Nov | B31: 717
A32: Dec | B32: 1401
A33: Grand Total | B33: 16651

Sheet 5
A3: Row Labels | B3: Count of Call number
A4: 2 | B4: 1
A5: 4 | B5: 1
A6: 6 | B6: 3
A7: 7 | B7: 1
A8: 8 | B8: 2
A9: 10 | B9: 1
A10: 11 | B10: 1
A11: 12 | B11: 1
A12: 13 | B12: 2
A13: 14 | B13: 1
A14: 15 | B14: 2
A15: 17 | B15: 2
... A167: 176 | B167: 1
A168: Grand Total | B168: 1000

Sheet 8
A3: Count of Call number | B3: Column Labels
A4: Row Labels | B4: Sunday | C4: Monday | D4: Tuesday | E4: Wednesday | F4: Thursday | G4: Friday | H4: Saturday | I4: Grand Total
A5: R01 | B5: 0.19047619 | C5: 0.15873016 | D5: 0.068783069 | E5: 0.12169312 | F5: 0.12169312 | G5: 0.12698413 | H5: 0.21164021 | I5: 1
A6: R02 | B6: 0.12844037 | C6: 0.11009174 | D6: 0.20183486 | E6: 0.16513761 | F6: 0.15137615 | G6: 0.13302752 | H6: 0.11009174 | I6: 1
A7: R03 | B7: 0.14492754 | C7: 0.16425121 | D7: 0.12560386 | E7: 0.18357488 | F7: 0.13043478 | G7: 0.13043478 | H7: 0.12077295 | I7: 1
A8: R04 | B8: 0.1344086 | C8: 0.12365591 | D8: 0.15053763 | E8: 0.15591398 | F8: 0.096774194 | G8: 0.15591398 | H8: 0.1827957 | I8: 1
A9: R05 | B9: 0.135 | C9: 0.11 | D9: 0.135 | E9: 0.135 | F9: 0.135 | G9: 0.16 | H9: 0.19 | I9: 1
A10: Grand Total | B10: 0.146 | C10: 0.133 | D10: 0.138 | E10: 0.153 | F10: 0.128 | G10: 0.141 | H10: 0.161 | I10: 1

Sheet 9
A3: Count of Call number | B3: Column Labels
A4: Row Labels | B4: 0 | C4: 1 | D4: 2 | E4: 3 | F4: 4 | G4: 5 | H4: Grand Total
A5: UNDER 10 MINS | B5: 0 | C5: 0 | D5: 0 | E5: 0.22222222 | F5: 0.55555556 | G5: 0.22222222 | H5: 1
A6: 10 TO 30 MINS | B6: 0 | C6: 0 | D6: 0.078431373 | E6: 0.11764706 | F6: 0.50980392 | G6: 0.29411765 | H6: 1
A7: 30 TO 60 MINS | B7: 0 | C7: 0 | D7: 0.072625698 | E7: 0.19553073 | F7: 0.41899441 | G7: 0.31284916 | H7: 1
A8: 1 TO 2 HRS | B8: 0 | C8: 0.0095419847 | D8: 0.053435115 | E8: 0.20229008 | F8: 0.42938931 | G8: 0.30534351 | H8: 1
A9: MORE THAN 2 HRS | B9: 0.0042194093 | C9: 0.012658228 | D9: 0.05907173 | E9: 0.20253165 | F9: 0.4092827 | G9: 0.31223629 | H9: 1
A10: Grand Total | B10: 0.001 | C10: 0.008 | D10: 0.059 | E10: 0.197 | F10: 0.428 | G10: 0.307 | H10: 1

Sheet 10
A3: Count of Call number | B3: Column Labels
A4: Row Labels | B4: Jan | C4: Feb | D4: Mar | E4: Apr | F4: May | G4: Jun | H4: Jul | I4: Aug | J4: Sep | K4: Oct | L4: Nov | M4: Dec | N4: Grand Total
A5: R01 | B5: 16 | C5: 14 | D5: 26 | E5: 29 | F5: 17 | G5: 15 | H5: 15 | I5: 7 | J5: 11 | K5: 24 | L5: 9 | M5: 6 | N5: 189
A6: R02 | B6: 19 | C6: 10 | D6: 40 | E6: 40 | F6: 13 | G6: 12 | H6: 9 | I6: 13 | J6: 18 | K6: 21 | L6: 14 | M6: 9 | N6: 218
A7: R03 | B7: 13 | C7: 13 | D7: 28 | E7: 24 | F7: 23 | G7: 17 | H7: 11 | I7: 11 | J7: 14 | K7: 30 | L7: 14 | M7: 9 | N7: 207
A8: R04 | B8: 10 | C8: 11 | D8: 30 | E8: 23 | F8: 22 | G8: 11 | H8: 17 | I8: 12 | J8: 13 | K8: 15 | L8: 8 | M8: 14 | N8: 186
A9: R05 | B9: 21 | C9: 18 | D9: 31 | E9: 20 | F9: 8 | G9: 12 | H9: 12 | I9: 7 | J9: 20 | K9: 24 | L9: 12 | M9: 15 | N9: 200
A10: Grand Total | B10: 79 | C10: 66 | D10: 155 | E10: 136 | F10: 83 | G10: 67 | H10: 64 | I10: 50 | J10: 76 | K10: 114 | L10: 57 | M10: 53 | N10: 1000

Sheet Sheet2
A3: CALL COUNT | B3: TOTAL AMOUNT | C3: TOTAL DURATION | D3: AVERAGE RATING | E3: 5*CALLS
A4: 1000 | B4: 96623 | C4: 89850 | D4: 3.8854 | E4: 307
A9: CALL COUNT | B9: TOTAL AMOUNT | C9: TOTAL DURATION | D9: AVERAGE RATING | E9: 5*CALLS
A10: 218 | B10: 20581 | C10: 19300 | D10: 3.8706422 | E10: 74
A15: Row Labels | B15: CALL COUNT | D15: Row Labels | E15: CALL COUNT
A16: Jan | B16: 19 | D16: Sunday | E16: 28
A17: Feb | B17: 10 | D17: Monday | E17: 24
A18: Mar | B18: 40 | D18: Tuesday | E18: 44
A19: Apr | B19: 40 | D19: Wednesday | E19: 36
A20: May | B20: 13 | D20: Thursday | E20: 33
A21: Jun | B21: 12 | D21: Friday | E21: 29
A22: Jul | B22: 9 | D22: Saturday | E22: 24
A23: Aug | B23: 13 | D23: Grand Total | E23: 218
A24: Sep | B24: 18
A25: Oct | B25: 21
A26: Nov | B26: 14
A27: Dec | B27: 9
A28: Grand Total | B28: 218
F34: rep | G34: calls | H34: amount | I34: sel.calls | J34: sel.amount
F36: {=A38:C42} -> R01 | G36: 189 | H36: 18415 | I36: =IF(A51=F36,G36,NA()) -> #N/A | J36: =IF(A51=F36,H36,NA()) -> #N/A
A37: Row Labels | B37: Count of Call number | C37: Sum of Purchase Amount | F37: R02 | G37: 218 | H37: 20581 | I37: =IF(A51=F37,G37,NA()) -> 218 | J37: =IF(A51=F37,H37,NA()) -> 20581
A38: R01 | B38: 189 | C38: 18415 | F38: R03 | G38: 207 | H38: 20872 | I38: =IF(A51=F38,G38,NA()) -> #N/A | J38: =IF(A51=F38,H38,NA()) -> #N/A
A39: R02 | B39: 218 | C39: 20581 | F39: R04 | G39: 186 | H39: 16651 | I39: =IF(A51=F39,G39,NA()) -> #N/A | J39: =IF(A51=F39,H39,NA()) -> #N/A
A40: R03 | B40: 207 | C40: 20872 | F40: R05 | G40: 200 | H40: 20104 | I40: =IF(A51=F40,G40,NA()) -> #N/A | J40: =IF(A51=F40,H40,NA()) -> #N/A
A41: R04 | B41: 186 | C41: 16651
A42: R05 | B42: 200 | C42: 20104
A43: Grand Total | B43: 1000 | C43: 96623
A50: Row Labels
A51: R02
A52: Grand Total
A58: Count of Call number | B58: Column Labels
A59: Row Labels | B59: Female | C59: Male | D59: Grand Total
A60: Cincinnati | B60: 144 | C60: 132 | D60: 276
A61: Cleveland | B61: 326 | C61: 63 | D61: 389
A62: Columbus | B62: 129 | C62: 206 | D62: 335
A63: Grand Total | B63: 599 | C63: 401 | D63: 1000
A68: Row Labels | B68: CALL COUNT
A69: 1 | B69: 3
A70: 2 | B70: 19
A71: 3 | B71: 35
...

Sheet Data
A4: Call number | B4: Customer ID | C4: Duration | D4: Representative | E4: Date of Call | F4: Purchase Amount | G4: Satisfaction Rating | H4: FY | I4: DAY OF WEEK | J4: DURATION BUCKET | K4: ROUND OFF | M4: Customer ID | N4: Gedner | O4: Age | P4: City
A5: Call_7271 | B5: C0003 | C5: 116 | D5: R05 | E5: 44927 | F5: 128 | G5: 4.9 | H5: =IF(MONTH(calls[[#This Row],[Date of Call]])<=6,YEAR(calls[[#This Row],[Date of Call]]),YEAR(calls[[#This Row],[Date of Call]])+1) -> 2023 | I5: =TEXT(calls[[#This Row],[Date of Call]],"DDDD") -> Sunday | J5: {=_xlfn.IFS(calls[[#This Row],[Duration]]<=10,"UNDER 10 MINS",calls[[#This Row],[Duration]]<=30,"10 TO 30 MINS",calls[[#This Row],[Duration]]<=60,"30 TO 60 MINS",calls[[#This Row],[Duration]]<=120,"1 TO 2 HRS",TRUE,"MORE THAN 2 HRS")} -> 1 TO 2 HRS | K5: =ROUND(calls[[#This Row],[Satisfaction Rating]],0) -> 5 | M5: C0001 | N5: Male | O5: 41 | P5: Columbus
A6: Call_7272 | B6: C0004 | C6: 119 | D6: R05 | E6: 44927 | F6: 135 | G6: 2.9 | H6: =IF(MONTH(calls[[#This Row],[Date of Call]])<=6,YEAR(calls[[#This Row],[Date of Call]]),YEAR(calls[[#This Row],[Date of Call]])+1) -> 2023 | I6: =TEXT(calls[[#This Row],[Date of Call]],"DDDD") -> Sunday | J6: {=_xlfn.IFS(calls[[#This Row],[Duration]]<=10,"UNDER 10 MINS",calls[[#This Row],[Duration]]<=30,"10 TO 30 MINS",calls[[#This Row],[Duration]]<=60,"30 TO 60 MINS",calls[[#This Row],[Duration]]<=120,"1 TO 2 HRS",TRUE,"MORE THAN 2 HRS")} -> 1 TO 2 HRS | K6: =ROUND(calls[[#This Row],[Satisfaction Rating]],0) -> 3 | M6: C0002 | N6: Male | O6: 31 | P6: Cleveland
A7: Call_7273 | B7: C0005 | C7: 68 | D7: R02 | E7: 44927 | F7: 66 | G7: 4.7 | H7: =IF(MONTH(calls[[#This Row],[Date of Call]])<=6,YEAR(calls[[#This Row],[Date of Call]]),YEAR(calls[[#This Row],[Date of Call]])+1) -> 2023 | I7: =TEXT(calls[[#This Row],[Date of Call]],"DDDD") -> Sunday | J7: {=_xlfn.IFS(calls[[#This Row],[Duration]]<=10,"UNDER 10 MINS",calls[[#This Row],[Duration]]<=30,"10 TO 30 MINS",calls[[#This Row],[Duration]]<=60,"30 TO 60 MINS",calls[[#This Row],[Duration]]<=120,"1 TO 2 HRS",TRUE,"MORE THAN 2 HRS")} -> 1 TO 2 HRS | K7: =ROUND(calls[[#This Row],[Satisfaction Rating]],0) -> 5 | M7: C0003 | N7: Male | O7: 26 | P7: Cincinnati
A8: Call_7274 | B8: C0014 | C8: 119 | D8: R02 | E8: 44927 | F8: 22 | G8: 2.9 | H8: =IF(MONTH(calls[[#This Row],[Date of Call]])<=6,YEAR(calls[[#This Row],[Date of Call]]),YEAR(calls[[#This Row],[Date of Call]])+1) -> 2023 | I8: =TEXT(calls[[#This Row],[Date of Call]],"DDDD") -> Sunday | J8: {=_xlfn.IFS(calls[[#This Row],[Duration]]<=10,"UNDER 10 MINS",calls[[#This Row],[Duration]]<=30,"10 TO 30 MINS",calls[[#This Row],[Duration]]<=60,"30 TO 60 MINS",calls[[#This Row],[Duration]]<=120,"1 TO 2 HRS",TRUE,"MORE THAN 2 HRS")} -> 1 TO 2 HRS | K8: =ROUND(calls[[#This Row],[Satisfaction Rating]],0) -> 3 | M8: C0004 | N8: Male | O8: 36 | P8: Cincinnati
A9: Call_7275 | B9: C0011 | C9: 128 | D9: R01 | E9: 44928 | F9: 31 | G9: 2.8 | H9: =IF(MONTH(calls[[#This Row],[Date of Call]])<=6,YEAR(calls[[#This Row],[Date of Call]]),YEAR(calls[[#This Row],[Date of Call]])+1) -> 2023 | I9: =TEXT(calls[[#This Row],[Date of Call]],"DDDD") -> Monday | J9: {=_xlfn.IFS(calls[[#This Row],[Duration]]<=10,"UNDER 10 MINS",calls[[#This Row],[Duration]]<=30,"10 TO 30 MINS",calls[[#This Row],[Duration]]<=60,"30 TO 60 MINS",calls[[#This Row],[Duration]]<=120,"1 TO 2 HRS",TRUE,"MORE THAN 2 HRS")} -> MORE THAN 2 HRS | K9: =ROUND(calls[[#This Row],[Satisfaction Rating]],0) -> 3 | M9: C0005 | N9: Male | O9: 37 | P9: Columbus
A10: Call_7276 | B10: C0011 | C10: 49 | D10: R02 | E10: 44929 | F10: 135 | G10: 4.8 | H10: =IF(MONTH(calls[[#This Row],[Date of Call]])<=6,YEAR(calls[[#This Row],[Date of Call]]),YEAR(calls[[#This Row],[Date of Call]])+1) -> 2023 | I10: =TEXT(calls[[#This Row],[Date of Call]],"DDDD") -> Tuesday | J10: {=_xlfn.IFS(calls[[#This Row],[Duration]]<=10,"UNDER 10 MINS",calls[[#This Row],[Duration]]<=30,"10 TO 30 MINS",calls[[#This Row],[Duration]]<=60,"30 TO 60 MINS",calls[[#This Row],[Duration]]<=120,"1 TO 2 HRS",TRUE,"MORE THAN 2 HRS")} -> 30 TO 60 MINS | K10: =ROUND(calls[[#This Row],[Satisfaction Rating]],0) -> 5 | M10: C0006 | N10: Male | O10: 23 | P10: Columbus
A11: Call_7277 | B11: C0007 | C11: 84 | D11: R05 | E11: 44929 | F11: 60 | G11: 4.7 | H11: =IF(MONTH(calls[[#This Row],[Date of Call]])<=6,YEAR(calls[[#This Row],[Date of Call]]),YEAR(calls[[#This Row],[Date of Call]])+1) -> 2023 | I11: =TEXT(calls[[#This Row],[Date of Call]],"DDDD") -> Tuesday | J11: {=_xlfn.IFS(calls[[#This Row],[Duration]]<=10,"UNDER 10 MINS",calls[[#This Row],[Duration]]<=30,"10 TO 30 MINS",calls[[#This Row],[Duration]]<=60,"30 TO 60 MINS",calls[[#This Row],[Duration]]<=120,"1 TO 2 HRS",TRUE,"MORE THAN 2 HRS")} -> 1 TO 2 HRS | K11: =ROUND(calls[[#This Row],[Satisfaction Rating]],0) -> 5 | M11: C0007 | N11: Female | O11: 22 | P11: Cleveland
A12: Call_7278 | B12: C0003 | C12: 103 | D12: R04 | E12: 44929 | F12: 148 | G12: 4.4 | H12: =IF(MONTH(calls[[#This Row],[Date of Call]])<=6,YEAR(calls[[#This Row],[Date of Call]]),YEAR(calls[[#This Row],[Date of Call]])+1) -> 2023 | I12: =TEXT(calls[[#This Row],[Date of Call]],"DDDD") -> Tuesday | J12: {=_xlfn.IFS(calls[[#This Row],[Duration]]<=10,"UNDER 10 MINS",calls[[#This Row],[Duration]]<=30,"10 TO 30 MINS",calls[[#This Row],[Duration]]<=60,"30 TO 60 MINS",calls[[#This Row],[Duration]]<=120,"1 TO 2 HRS",TRUE,"MORE THAN 2 HRS")} -> 1 TO 2 HRS | K12: =ROUND(calls[[#This Row],[Satisfaction Rating]],0) -> 4 | M12: C0008 | N12: Female | O12: 42 | P12: Cleveland
A13: Call_7279 | B13: C0005 | C13: 31 | D13: R02 | E13: 44929 | F13: 135 | G13: 3.6 | H13: =IF(MONTH(calls[[#This Row],[Date of Call]])<=6,YEAR(calls[[#This Row],[Date of Call]]),YEAR(calls[[#This Row],[Date of Call]])+1) -> 2023 | I13: =TEXT(calls[[#This Row],[Date of Call]],"DDDD") -> Tuesday | J13: {=_xlfn.IFS(calls[[#This Row],[Duration]]<=10,"UNDER 10 MINS",calls[[#This Row],[Duration]]<=30,"10 TO 30 MINS",calls[[#This Row],[Duration]]<=60,"30 TO 60 MINS",calls[[#This Row],[Duration]]<=120,"1 TO 2 HRS",TRUE,"MORE THAN 2 HRS")} -> 30 TO 60 MINS | K13: =ROUND(calls[[#This Row],[Satisfaction Rating]],0) -> 4 | M13: C0009 | N13: Female | O13: 25 | P13: Columbus
A14: Call_7280 | B14: C0010 | C14: 44 | D14: R03 | E14: 44929 | F14: 105 | G14: 2.9 | H14: =IF(MONTH(calls[[#This Row],[Date of Call]])<=6,YEAR(calls[[#This Row],[Date of Call]]),YEAR(calls[[#This Row],[Date of Call]])+1) -> 2023 | I14: =TEXT(calls[[#This Row],[Date of Call]],"DDDD") -> Tuesday | J14: {=_xlfn.IFS(calls[[#This Row],[Duration]]<=10,"UNDER 10 MINS",calls[[#This Row],[Duration]]<=30,"10 TO 30 MINS",calls[[#This Row],[Duration]]<=60,"30 TO 60 MINS",calls[[#This Row],[Duration]]<=120,"1 TO 2 HRS",TRUE,"MORE THAN 2 HRS")} -> 30 TO 60 MINS | K14: =ROUND(calls[[#This Row],[Satisfaction Rating]],0) -> 3 | M14: C0010 | N14: Female | O14: 30 | P14: Cleveland
A15: Call_7281 | B15: C0011 | C15: 102 | D15: R02 | E15: 44929 | F15: 69 | G15: 4.9 | H15: =IF(MONTH(calls[[#This Row],[Date of Call]])<=6,YEAR(calls[[#This Row],[Date of Call]]),YEAR(calls[[#This Row],[Date of Call]])+1) -> 2023 | I15: =TEXT(calls[[#This Row],[Date of Call]],"DDDD") -> Tuesday | J15: {=_xlfn.IFS(calls[[#This Row],[Duration]]<=10,"UNDER 10 MINS",calls[[#This Row],[Duration]]<=30,"10 TO 30 MINS",calls[[#This Row],[Duration]]<=60,"30 TO 60 MINS",calls[[#This Row],[Duration]]<=120,"1 TO 2 HRS",TRUE,"MORE THAN 2 HRS")} -> 1 TO 2 HRS | K15: =ROUND(calls[[#This Row],[Satisfaction Rating]],0) -> 5 | M15: C0011 | N15: Female | O15: 30 | P15: Cincinnati
A16: Call_7282 | B16: C0013 | C16: 135 | D16: R05 | E16: 44929 | F16: 46 | G16: 3.4 | H16: =IF(MONTH(calls[[#This Row],[Date of Call]])<=6,YEAR(calls[[#This Row],[Date of Call]]),YEAR(calls[[#This Row],[Date of Call]])+1) -> 2023 | I16: =TEXT(calls[[#This Row],[Date of Call]],"DDDD") -> Tuesday | J16: {=_xlfn.IFS(calls[[#This Row],[Duration]]<=10,"UNDER 10 MINS",calls[[#This Row],[Duration]]<=30,"10 TO 30 MINS",calls[[#This Row],[Duration]]<=60,"30 TO 60 MINS",calls[[#This Row],[Duration]]<=120,"1 TO 2 HRS",TRUE,"MORE THAN 2 HRS")} -> MORE THAN 2 HRS | K16: =ROUND(calls[[#This Row],[Satisfaction Rating]],0) -> 3 | M16: C0012 | N16: Female | O16: 28 | P16: Cincinnati
... A19: Call_7285 | B19: C0013 | C19: 48 | D19: R01 | E19: 44930 | F19: 68 | G19: 4.9 | H19: =IF(MONTH(calls[[#This Row],[Date of Call]])<=6,YEAR(calls[[#This Row],[Date of Call]]),YEAR(calls[[#This Row],[Date of Call]])+1) -> 2023 | I19: =TEXT(calls[[#This Row],[Date of Call]],"DDDD") -> Wednesday | J19: {=_xlfn.IFS(calls[[#This Row],[Duration]]<=10,"UNDER 10 MINS",calls[[#This Row],[Duration]]<=30,"10 TO 30 MINS",calls[[#This Row],[Duration]]<=60,"30 TO 60 MINS",calls[[#This Row],[Duration]]<=120,"1 TO 2 HRS",TRUE,"MORE THAN 2 HRS")} -> 30 TO 60 MINS | K19: =ROUND(calls[[#This Row],[Satisfaction Rating]],0) -> 5 | M19: C0015 | N19: Female | O19: 43 | P19: Cleveland
A20: Call_7286 | B20: C0010 | C20: 176 | D20: R05 | E20: 44931 | F20: 24 | G20: 4.8 | H20: =IF(MONTH(calls[[#This Row],[Date of Call]])<=6,YEAR(calls[[#This Row],[Date of Call]]),YEAR(calls[[#This Row],[Date of Call]])+1) -> 2023 | I20: =TEXT(calls[[#This Row],[Date of Call]],"DDDD") -> Thursday | J20: {=_xlfn.IFS(calls[[#This Row],[Duration]]<=10,"UNDER 10 MINS",calls[[#This Row],[Duration]]<=30,"10 TO 30 MINS",calls[[#This Row],[Duration]]<=60,"30 TO 60 MINS",calls[[#This Row],[Duration]]<=120,"1 TO 2 HRS",TRUE,"MORE THAN 2 HRS")} -> MORE THAN 2 HRS | K20: =ROUND(calls[[#This Row],[Satisfaction Rating]],0) -> 5
A21: Call_7287 | B21: C0010 | C21: 99 | D21: R01 | E21: 44931 | F21: 195 | G21: 3.9 | H21: =IF(MONTH(calls[[#This Row],[Date of Call]])<=6,YEAR(calls[[#This Row],[Date of Call]]),YEAR(calls[[#This Row],[Date of Call]])+1) -> 2023 | I21: =TEXT(calls[[#This Row],[Date of Call]],"DDDD") -> Thursday | J21: {=_xlfn.IFS(calls[[#This Row],[Duration]]<=10,"UNDER 10 MINS",calls[[#This Row],[Duration]]<=30,"10 TO 30 MINS",calls[[#This Row],[Duration]]<=60,"30 TO 60 MINS",calls[[#This Row],[Duration]]<=120,"1 TO 2 HRS",TRUE,"MORE THAN 2 HRS")} -> 1 TO 2 HRS | K21: =ROUND(calls[[#This Row],[Satisfaction Rating]],0) -> 4
A22: Call_7288 | B22: C0009 | C22: 28 | D22: R03 | E22: 44931 | F22: 28 | G22: 3.8 | H22: =IF(MONTH(calls[[#This Row],[Date of Call]])<=6,YEAR(calls[[#This Row],[Date of Call]]),YEAR(calls[[#This Row],[Date of Call]])+1) -> 2023 | I22: =TEXT(calls[[#This Row],[Date of Call]],"DDDD") -> Thursday | J22: {=_xlfn.IFS(calls[[#This Row],[Duration]]<=10,"UNDER 10 MINS",calls[[#This Row],[Duration]]<=30,"10 TO 30 MINS",calls[[#This Row],[Duration]]<=60,"30 TO 60 MINS",calls[[#This Row],[Duration]]<=120,"1 TO 2 HRS",TRUE,"MORE THAN 2 HRS")} -> 10 TO 30 MINS | K22: =ROUND(calls[[#This Row],[Satisfaction Rating]],0) -> 4
A23: Call_7289 | B23: C0007 | C23: 54 | D23: R02 | E23: 44931 | F23: 170 | G23: 4.3 | H23: =IF(MONTH(calls[[#This Row],[Date of Call]])<=6,YEAR(calls[[#This Row],[Date of Call]]),YEAR(calls[[#This Row],[Date of Call]])+1) -> 2023 | I23: =TEXT(calls[[#This Row],[Date of Call]],"DDDD") -> Thursday | J23: {=_xlfn.IFS(calls[[#This Row],[Duration]]<=10,"UNDER 10 MINS",calls[[#This Row],[Duration]]<=30,"10 TO 30 MINS",calls[[#This Row],[Duration]]<=60,"30 TO 60 MINS",calls[[#This Row],[Duration]]<=120,"1 TO 2 HRS",TRUE,"MORE THAN 2 HRS")} -> 30 TO 60 MINS | K23: =ROUND(calls[[#This Row],[Satisfaction Rating]],0) -> 4
A24: Call_7290 | B24: C0006 | C24: 48 | D24: R05 | E24: 44932 | F24: 30 | G24: 4.4 | H24: =IF(MONTH(calls[[#This Row],[Date of Call]])<=6,YEAR(calls[[#This Row],[Date of Call]]),YEAR(calls[[#This Row],[Date of Call]])+1) -> 2023 | I24: =TEXT(calls[[#This Row],[Date of Call]],"DDDD") -> Friday | J24: {=_xlfn.IFS(calls[[#This Row],[Duration]]<=10,"UNDER 10 MINS",calls[[#This Row],[Duration]]<=30,"10 TO 30 MINS",calls[[#This Row],[Duration]]<=60,"30 TO 60 MINS",calls[[#This Row],[Duration]]<=120,"1 TO 2 HRS",TRUE,"MORE THAN 2 HRS")} -> 30 TO 60 MINS | K24: =ROUND(calls[[#This Row],[Satisfaction Rating]],0) -> 4
A25: Call_7291 | B25: C0004 | C25: 128 | D25: R05 | E25: 44932 | F25: 72 | G25: 5 | H25: =IF(MONTH(calls[[#This Row],[Date of Call]])<=6,YEAR(calls[[#This Row],[Date of Call]]),YEAR(calls[[#This Row],[Date of Call]])+1) -> 2023 | I25: =TEXT(calls[[#This Row],[Date of Call]],"DDDD") -> Friday | J25: {=_xlfn.IFS(calls[[#This Row],[Duration]]<=10,"UNDER 10 MINS",calls[[#This Row],[Duration]]<=30,"10 TO 30 MINS",calls[[#This Row],[Duration]]<=60,"30 TO 60 MINS",calls[[#This Row],[Duration]]<=120,"1 TO 2 HRS",TRUE,"MORE THAN 2 HRS")} -> MORE THAN 2 HRS | K25: =ROUND(calls[[#This Row],[Satisfaction Rating]],0) -> 5
A26: Call_7292 | B26: C0004 | C26: 38 | D26: R04 | E26: 44933 | F26: 92 | G26: 4.9 | H26: =IF(MONTH(calls[[#This Row],[Date of Call]])<=6,YEAR(calls[[#This Row],[Date of Call]]),YEAR(calls[[#This Row],[Date of Call]])+1) -> 2023 | I26: =TEXT(calls[[#This Row],[Date of Call]],"DDDD") -> Saturday | J26: {=_xlfn.IFS(calls[[#This Row],[Duration]]<=10,"UNDER 10 MINS",calls[[#This Row],[Duration]]<=30,"10 TO 30 MINS",calls[[#This Row],[Duration]]<=60,"30 TO 60 MINS",calls[[#This Row],[Duration]]<=120,"1 TO 2 HRS",TRUE,"MORE THAN 2 HRS")} -> 30 TO 60 MINS | K26: =ROUND(calls[[#This Row],[Satisfaction Rating]],0) -> 5
A27: Call_7293 | B27: C0003 | C27: 67 | D27: R04 | E27: 44934 | F27: 165 | G27: 4.5 | H27: =IF(MONTH(calls[[#This Row],[Date of Call]])<=6,YEAR(calls[[#This Row],[Date of Call]]),YEAR(calls[[#This Row],[Date of Call]])+1) -> 2023 | I27: =TEXT(calls[[#This Row],[Date of Call]],"DDDD") -> Sunday | J27: {=_xlfn.IFS(calls[[#This Row],[Duration]]<=10,"UNDER 10 MINS",calls[[#This Row],[Duration]]<=30,"10 TO 30 MINS",calls[[#This Row],[Duration]]<=60,"30 TO 60 MINS",calls[[#This Row],[Duration]]<=120,"1 TO 2 HRS",TRUE,"MORE THAN 2 HRS")} -> 1 TO 2 HRS | K27: =ROUND(calls[[#This Row],[Satisfaction Rating]],0) -> 5
A28: Call_7294 | B28: C0015 | C28: 58 | D28: R02 | E28: 44934 | F28: 140 | G28: 2.1 | H28: =IF(MONTH(calls[[#This Row],[Date of Call]])<=6,YEAR(calls[[#This Row],[Date of Call]]),YEAR(calls[[#This Row],[Date of Call]])+1) -> 2023 | I28: =TEXT(calls[[#This Row],[Date of Call]],"DDDD") -> Sunday | J28: {=_xlfn.IFS(calls[[#This Row],[Duration]]<=10,"UNDER 10 MINS",calls[[#This Row],[Duration]]<=30,"10 TO 30 MINS",calls[[#This Row],[Duration]]<=60,"30 TO 60 MINS",calls[[#This Row],[Duration]]<=120,"1 TO 2 HRS",TRUE,"MORE THAN 2 HRS")} -> 30 TO 60 MINS | K28: =ROUND(calls[[#This Row],[Satisfaction Rating]],0) -> 2
A29: Call_7295 | B29: C0010 | C29: 54 | D29: R01 | E29: 44934 | F29: 111 | G29: 3.3 | H29: =IF(MONTH(calls[[#This Row],[Date of Call]])<=6,YEAR(calls[[#This Row],[Date of Call]]),YEAR(calls[[#This Row],[Date of Call]])+1) -> 2023 | I29: =TEXT(calls[[#This Row],[Date of Call]],"DDDD") -> Sunday | J29: {=_xlfn.IFS(calls[[#This Row],[Duration]]<=10,"UNDER 10 MINS",calls[[#This Row],[Duration]]<=30,"10 TO 30 MINS",calls[[#This Row],[Duration]]<=60,"30 TO 60 MINS",calls[[#This Row],[Duration]]<=120,"1 TO 2 HRS",TRUE,"MORE THAN 2 HRS")} -> 30 TO 60 MINS | K29: =ROUND(calls[[#This Row],[Satisfaction Rating]],0) -> 3
A30: Call_7296 | B30: C0012 | C30: 28 | D30: R05 | E30: 44935 | F30: 63 | G30: 4.1 | H30: =IF(MONTH(calls[[#This Row],[Date of Call]])<=6,YEAR(calls[[#This Row],[Date of Call]]),YEAR(calls[[#This Row],[Date of Call]])+1) -> 2023 | I30: =TEXT(calls[[#This Row],[Date of Call]],"DDDD") -> Monday | J30: {=_xlfn.IFS(calls[[#This Row],[Duration]]<=10,"UNDER 10 MINS",calls[[#This Row],[Duration]]<=30,"10 TO 30 MINS",calls[[#This Row],[Duration]]<=60,"30 TO 60 MINS",calls[[#This Row],[Duration]]<=120,"1 TO 2 HRS",TRUE,"MORE THAN 2 HRS")} -> 10 TO 30 MINS | K30: =ROUND(calls[[#This Row],[Satisfaction Rating]],0) -> 4
A31: Call_7297 | B31: C0002 | C31: 73 | D31: R05 | E31: 44935 | F31: 80 | G31: 4.2 | H31: =IF(MONTH(calls[[#This Row],[Date of Call]])<=6,YEAR(calls[[#This Row],[Date of Call]]),YEAR(calls[[#This Row],[Date of Call]])+1) -> 2023 | I31: =TEXT(calls[[#This Row],[Date of Call]],"DDDD") -> Monday | J31: {=_xlfn.IFS(calls[[#This Row],[Duration]]<=10,"UNDER 10 MINS",calls[[#This Row],[Duration]]<=30,"10 TO 30 MINS",calls[[#This Row],[Duration]]<=60,"30 TO 60 MINS",calls[[#This Row],[Duration]]<=120,"1 TO 2 HRS",TRUE,"MORE THAN 2 HRS")} -> 1 TO 2 HRS | K31: =ROUND(calls[[#This Row],[Satisfaction Rating]],0) -> 4
... A1004: Call_8270 | B1004: C0009 | C1004: 114 | D1004: R01 | E1004: 45291 | F1004: 40 | G1004: 3.9 | H1004: =IF(MONTH(calls[[#This Row],[Date of Call]])<=6,YEAR(calls[[#This Row],[Date of Call]]),YEAR(calls[[#This Row],[Date of Call]])+1) -> 2024 | I1004: =TEXT(calls[[#This Row],[Date of Call]],"DDDD") -> Sunday | J1004: {=_xlfn.IFS(calls[[#This Row],[Duration]]<=10,"UNDER 10 MINS",calls[[#This Row],[Duration]]<=30,"10 TO 30 MINS",calls[[#This Row],[Duration]]<=60,"30 TO 60 MINS",calls[[#This Row],[Duration]]<=120,"1 TO 2 HRS",TRUE,"MORE THAN 2 HRS")} -> 1 TO 2 HRS | K1004: =ROUND(calls[[#This Row],[Satisfaction Rating]],0) -> 4

Sheet PROJECT
P14: R01 | Q14: R02 | R14: R03 | S14: R04 | T14: R05 | U14: Total
O15: =Sheet2!A80 -> Cincinnati
O16: =Sheet2!A81 -> C0003 | P16: =Sheet2!B81 -> 891 | Q16: =Sheet2!C81 -> 1332 | R16: =Sheet2!D81 -> 1282 | S16: =Sheet2!E81 -> 739 | T16: =Sheet2!F81 -> 560 | U16: =Sheet2!G81 -> 4804
O17: =Sheet2!A82 -> C0004 | P17: =Sheet2!B82 -> 1991 | Q17: =Sheet2!C82 -> 1886 | R17: =Sheet2!D82 -> 1206 | S17: =Sheet2!E82 -> 884 | T17: =Sheet2!F82 -> 1722 | U17: =Sheet2!G82 -> 7689
O18: =Sheet2!A83 -> C0011 | P18: =Sheet2!B83 -> 1163 | Q18: =Sheet2!C83 -> 1180 | R18: =Sheet2!D83 -> 1616 | S18: =Sheet2!E83 -> 1043 | T18: =Sheet2!F83 -> 1747 | U18: =Sheet2!G83 -> 6749
O19: =Sheet2!A84 -> C0012 | P19: =Sheet2!B84 -> 1438 | Q19: =Sheet2!C84 -> 1616 | R19: =Sheet2!D84 -> 866 | S19: =Sheet2!E84 -> 829 | T19: =Sheet2!F84 -> 2070 | U19: =Sheet2!G84 -> 6819
O20: =Sheet2!A85 -> Cleveland
O21: =Sheet2!A86 -> C0002 | P21: =Sheet2!B86 -> 1233 | Q21: =Sheet2!C86 -> 223 | R21: =Sheet2!D86 -> 1680 | S21: =Sheet2!E86 -> 990 | T21: =Sheet2!F86 -> 1508 | U21: =Sheet2!G86 -> 5634
O22: =Sheet2!A87 -> C0007 | P22: =Sheet2!B87 -> 1598 | Q22: =Sheet2!C87 -> 1907 | R22: =Sheet2!D87 -> 869 | S22: =Sheet2!E87 -> 1426 | T22: =Sheet2!F87 -> 1416 | U22: =Sheet2!G87 -> 7216
O23: =Sheet2!A88 -> C0008 | P23: =Sheet2!B88 -> 900 | Q23: =Sheet2!C88 -> 1016 | R23: =Sheet2!D88 -> 960 | S23: =Sheet2!E88 -> 940 | T23: =Sheet2!F88 -> 1193 | U23: =Sheet2!G88 -> 5009
O24: =Sheet2!A89 -> C0010 | P24: =Sheet2!B89 -> 900 | Q24: =Sheet2!C89 -> 1470 | R24: =Sheet2!D89 -> 1617 | S24: =Sheet2!E89 -> 1314 | T24: =Sheet2!F89 -> 941 | U24: =Sheet2!G89 -> 6242
O25: =Sheet2!A90 -> C0013 | P25: =Sheet2!B90 -> 1255 | Q25: =Sheet2!C90 -> 516 | R25: =Sheet2!D90 -> 1874 | S25: =Sheet2!E90 -> 1863 | T25: =Sheet2!F90 -> 1722 | U25: =Sheet2!G90 -> 7230
O26: =Sheet2!A91 -> C0015 | P26: =Sheet2!B91 -> 1138 | Q26: =Sheet2!C91 -> 1898 | R26: =Sheet2!D91 -> 1482 | S26: =Sheet2!E91 -> 846 | T26: =Sheet2!F91 -> 1154 | U26: =Sheet2!G91 -> 6518
O27: =Sheet2!A92 -> Columbus
O28: =Sheet2!A93 -> C0001 | P28: =Sheet2!B93 -> 1655 | Q28: =Sheet2!C93 -> 805 | R28: =Sheet2!D93 -> 2263 | S28: =Sheet2!E93 -> 987 | T28: =Sheet2!F93 -> 1075 | U28: =Sheet2!G93 -> 6785
O29: =Sheet2!A94 -> C0005 | P29: =Sheet2!B94 -> 1104 | Q29: =Sheet2!C94 -> 2280 | R29: =Sheet2!D94 -> 1445 | S29: =Sheet2!E94 -> 1722 | T29: =Sheet2!F94 -> 1196 | U29: =Sheet2!G94 -> 7747
O30: =Sheet2!A95 -> C0006 | P30: =Sheet2!B95 -> 372 | Q30: =Sheet2!C95 -> 1818 | R30: =Sheet2!D95 -> 1346 | S30: =Sheet2!E95 -> 1156 | T30: =Sheet2!F95 -> 1484 | U30: =Sheet2!G95 -> 6176
O31: =Sheet2!A96 -> C0009 | P31: =Sheet2!B96 -> 1415 | Q31: =Sheet2!C96 -> 1271 | R31: =Sheet2!D96 -> 1214 | S31: =Sheet2!E96 -> 1135 | T31: =Sheet2!F96 -> 1566 | U31: =Sheet2!G96 -> 6601
O32: =Sheet2!A97 -> C0014 | P32: =Sheet2!B97 -> 1362 | Q32: =Sheet2!C97 -> 1363 | R32: =Sheet2!D97 -> 1152 | S32: =Sheet2!E97 -> 777 | T32: =Sheet2!F97 -> 750 | U32: =Sheet2!G97 -> 5404
